Workbook
Name CAR_BEDS: Inputs!$B$37
Name CAR_CAP: Inputs!$B$26
Name CAR_DIM: Inputs!$B$23
Name CAR_FERT: Inputs!$B$24
Name CAR_HPB: Inputs!$B$22
Name CAR_PRICE: Inputs!$B$25
Name FARM_BED_CAP: Inputs!$B$13
Name FARMER_SALARY: Inputs!$B$8
Name FIXED_COST: Inputs!$B$12
Name MES_BEDS: Inputs!$B$38
Name MES_CAP: Inputs!$B$31
Name MES_DIM: Inputs!$B$28
Name MES_FERT: Inputs!$B$29
Name MES_HPB: Inputs!$B$27
Name MES_PRICE: Inputs!$B$30
Name OUT_BEDS_IDLE: Optimization!$B$10
Name OUT_BEDS_USED: Optimization!$B$9
Name OUT_BLENDED_RATE: Optimization!$B$23
Name OUT_CAR_BEDS: Optimization!$B$7
Name OUT_CONSTRAINTS_OK: Validation!$B$14
Name OUT_CROP_FERT_COST: Optimization!$E$37:$E$39
Name OUT_CROP_LABOR_COST: Optimization!$F$37:$F$39
Name OUT_CROP_PROFIT: Optimization!$G$37:$G$39
Name OUT_CROP_REVENUE: Optimization!$D$37:$D$39
Name OUT_CROSSING_CAR: 'Marginal Analysis'!$B$93
Name OUT_CROSSING_MES: 'Marginal Analysis'!$B$94
Name OUT_CROSSING_TOM: 'Marginal Analysis'!$B$92
Name OUT_FERT_COST: Optimization!$B$29
Name OUT_FIXED_COST: Optimization!$B$30
Name OUT_LABOR_COST: Optimization!$B$28
Name OUT_MC_SCHEDULE: 'Marginal Analysis'!$G$8:$G$27,'Marginal Analysis'!$G$33:$G$52,'Marginal Analysis'!$G$58:$G$87
Name OUT_MES_BEDS: Optimization!$B$8
Name OUT_P_MINUS_MC: 'Marginal Analysis'!$I$8:$I$27,'Marginal Analysis'!$I$33:$I$52,'Marginal Analysis'!$I$58:$I$87
Name OUT_PERM_HOURS: Optimization!$B$18
Name OUT_PNL_RECONCILES: Optimization!$B$44
Name OUT_REVENUE: Optimization!$B$27
Name OUT_SEASON_PROFIT: Optimization!$B$32
Name OUT_TEMP_HOURS: Optimization!$B$19
Name OUT_TEMP_WORKERS: Optimization!$B$20
Name OUT_TOM_BEDS: Optimization!$B$6
Name OUT_TOM_DIP_BED: 'Marginal Analysis'!$B$95
Name OUT_TOM_DIP_SIZE: 'Marginal Analysis'!$B$96
Name OUT_TOTAL_COST: Optimization!$B$31
Name OUT_TOTAL_HOURS: Optimization!$B$17
Name PERM_HOURS: Inputs!$B$7
Name PERM_RATE: Inputs!$B$42
Name TEMP_RATE: Inputs!$B$43
Name TEMP_WORKER_HRS: Inputs!$B$10
Name TEMP_WORKER_PAY: Inputs!$B$9
Name TEMP_WORKERS_MAX: Inputs!$B$11
Name TOM_BEDS: Inputs!$B$36
Name TOM_CAP: Inputs!$B$21
Name TOM_DIM: Inputs!$B$18
Name TOM_FERT: Inputs!$B$19
Name TOM_HPB: Inputs!$B$17
Name TOM_PRICE: Inputs!$B$20
Name WEEKS: Inputs!$B$6

Sheet Inputs
A1: Farm Labor & Profit Model — Inputs
A2: Every input below is a named range carrying its stated unit. Shaded cells are the only typed constants in the workbook; everything else, on every sheet, is a formula.
A4: Farm-wide assumptions
A5: Name | B5: Value | C5: Unit | D5: Source
A6: WEEKS | B6: 36 | C6: weeks | D6: Case scenario — season length
A7: PERM_HOURS | B7: 720 | C7: hours per season | D7: Case scenario — half the farmer's season
A8: FARMER_SALARY | B8: 50000 | C8: $ per season | D8: Case scenario
A9: TEMP_WORKER_PAY | B9: 25000 | C9: $ per worker per season | D9: Case scenario
A10: TEMP_WORKER_HRS | B10: 1440 | C10: hours per worker per season | D10: Case scenario
A11: TEMP_WORKERS_MAX | B11: 4 | C11: workers | D11: Case scenario constraint
A12: FIXED_COST | B12: 20000 | C12: $ per season | D12: Case scenario
A13: FARM_BED_CAP | B13: 64 | C13: beds | D13: Case scenario — 16 beds x 4 plots
A15: Per-crop assumptions
A16: Name | B16: Value | C16: Unit | D16: Source
A17: TOM_HPB | B17: 2.5 | C17: hours per week per bed | D17: Case table
A18: TOM_DIM | B18: 0.1 | C18: fraction, per bed | D18: Case table
A19: TOM_FERT | B19: 880 | C19: $ per bed | D19: Case table
A20: TOM_PRICE | B20: 8800 | C20: $ per bed | D20: Case table
A21: TOM_CAP | B21: 20 | C21: beds | D21: Case table
A22: CAR_HPB | B22: =5/6 -> 0.83333333 | C22: hours per week per bed | D22: Case shows 0.833; that figure is rounded. Entered as =5/6 to hold exact precision (spec Convention 1).
A23: CAR_DIM | B23: 0.025 | C23: fraction, per bed | D23: Case table
A24: CAR_FERT | B24: 440 | C24: $ per bed | D24: Case table
A25: CAR_PRICE | B25: 2094 | C25: $ per bed | D25: Case table
A26: CAR_CAP | B26: 20 | C26: beds | D26: Case table
A27: MES_HPB | B27: 1.25 | C27: hours per week per bed | D27: Case table
A28: MES_DIM | B28: 0.0125 | C28: fraction, per bed | D28: Case table
A29: MES_FERT | B29: 880 | C29: $ per bed | D29: Case table
A30: MES_PRICE | B30: 2700 | C30: $ per bed | D30: Case table
A31: MES_CAP | B31: 30 | C31: beds | D31: Case table
A33: Decision variables — the Solver changing cells
A34: Whole beds only: a bed is planted or it is not. These three cells are the only cells Solver changes.
A35: Name | B35: Value | C35: Unit | D35: Lower bound | E35: Upper bound
A36: TOM_BEDS | B36: 10 | C36: beds, integer | D36: 0 | E36: =TOM_CAP -> 20
A37: CAR_BEDS | B37: 20 | C37: beds, integer | D37: 0 | E37: =CAR_CAP -> 20
A38: MES_BEDS | B38: 30 | C38: beds, integer | D38: 0 | E38: =MES_CAP -> 30
A40: Derived rates — never entered as constants (spec §1, §3C)
A41: Name | B41: Value | C41: Unit | D41: Formula
A42: PERM_RATE | B42: =FARMER_SALARY/2/PERM_HOURS -> 34.722222 | C42: $ per hour | D42: FARMER_SALARY / 2 / PERM_HOURS (prints as 34.72; the exact quotient governs)
A43: TEMP_RATE | B43: =TEMP_WORKER_PAY/TEMP_WORKER_HRS -> 17.361111 | C43: $ per hour | D43: TEMP_WORKER_PAY / TEMP_WORKER_HRS (prints as 17.36; the exact quotient governs)

Sheet Marginal Analysis
A1: Cost / Marginal Analysis — three standalone schedules
A2: One schedule per crop, each built as though that crop were the only thing planted and each drawing on the full 720 permanent hours by itself (spec Convention 5). MC(q) is per crop: the labor cost of that crop's qth bed plus one bed of fertilizer. It excludes FIXED_COST.
A3: Permanent hours are consumed first, one bed at a time, so a single bed can be split across both rates (spec §3F). The Decision column implements the crossing rule of V7: the schedule stops at the FIRST bed whose marginal cost exceeds price and stays stopped, whatever MC does further down the column.
A5: TOMATOES — standalone schedule (q = 0 to TOM_CAP)
A6: q (beds) | B6: LABOR_HRS(q) | C6: MARGINAL_HRS(q) | D6: PERM_HRS(q) | E6: TEMP_HRS(q) | F6: Fertilizer, 1 bed | G6: MC(q) | H6: Price per bed | I6: P - MC(q) | J6: Decision (V7) | K6: Dip flag | L6: Cumulative VC(q) | M6: AVC(q)
A7: 0 | B7: =A7*TOM_HPB*WEEKS*(1+TOM_DIM)^A7 -> 0
A8: 1 | B8: =A8*TOM_HPB*WEEKS*(1+TOM_DIM)^A8 -> 99 | C8: =B8-B7 -> 99 | D8: =MAX(0,MIN(C8,PERM_HOURS-B7)) -> 99 | E8: =C8-D8 -> 0 | F8: =TOM_FERT -> 880 | G8: =D8*PERM_RATE+E8*TEMP_RATE+F8 -> 4317.5 | H8: =TOM_PRICE -> 8800 | I8: =H8-G8 -> 4482.5 | J8: =IF(COUNTIF($I$8:I8,"<0")>0,"Stop","Plant") -> Plant | K8: =IF(A8<2,0,IF(G8<G7,1,0)) -> 0 | L8: =SUM($G$8:G8) -> 4317.5 | M8: =L8/A8 -> 4317.5
A9: 2 | B9: =A9*TOM_HPB*WEEKS*(1+TOM_DIM)^A9 -> 217.8 | C9: =B9-B8 -> 118.8 | D9: =MAX(0,MIN(C9,PERM_HOURS-B8)) -> 118.8 | E9: =C9-D9 -> 0 | F9: =TOM_FERT -> 880 | G9: =D9*PERM_RATE+E9*TEMP_RATE+F9 -> 5005 | H9: =TOM_PRICE -> 8800 | I9: =H9-G9 -> 3795 | J9: =IF(COUNTIF($I$8:I9,"<0")>0,"Stop","Plant") -> Plant | K9: =IF(A9<2,0,IF(G9<G8,1,0)) -> 0 | L9: =SUM($G$8:G9) -> 9322.5 | M9: =L9/A9 -> 4661.25
A10: 3 | B10: =A10*TOM_HPB*WEEKS*(1+TOM_DIM)^A10 -> 359.37 | C10: =B10-B9 -> 141.57 | D10: =MAX(0,MIN(C10,PERM_HOURS-B9)) -> 141.57 | E10: =C10-D10 -> 0 | F10: =TOM_FERT -> 880 | G10: =D10*PERM_RATE+E10*TEMP_RATE+F10 -> 5795.625 | H10: =TOM_PRICE -> 8800 | I10: =H10-G10 -> 3004.375 | J10: =IF(COUNTIF($I$8:I10,"<0")>0,"Stop","Plant") -> Plant | K10: =IF(A10<2,0,IF(G10<G9,1,0)) -> 0 | L10: =SUM($G$8:G10) -> 15118.125 | M10: =L10/A10 -> 5039.375
A11: 4 | B11: =A11*TOM_HPB*WEEKS*(1+TOM_DIM)^A11 -> 527.076 | C11: =B11-B10 -> 167.706 | D11: =MAX(0,MIN(C11,PERM_HOURS-B10)) -> 167.706 | E11: =C11-D11 -> 0 | F11: =TOM_FERT -> 880 | G11: =D11*PERM_RATE+E11*TEMP_RATE+F11 -> 6703.125 | H11: =TOM_PRICE -> 8800 | I11: =H11-G11 -> 2096.875 | J11: =IF(COUNTIF($I$8:I11,"<0")>0,"Stop","Plant") -> Plant | K11: =IF(A11<2,0,IF(G11<G10,1,0)) -> 0 | L11: =SUM($G$8:G11) -> 21821.25 | M11: =L11/A11 -> 5455.3125
A12: 5 | B12: =A12*TOM_HPB*WEEKS*(1+TOM_DIM)^A12 -> 724.7295 | C12: =B12-B11 -> 197.6535 | D12: =MAX(0,MIN(C12,PERM_HOURS-B11)) -> 192.924 | E12: =C12-D12 -> 4.7295 | F12: =TOM_FERT -> 880 | G12: =D12*PERM_RATE+E12*TEMP_RATE+F12 -> 7660.8594 | H12: =TOM_PRICE -> 8800 | I12: =H12-G12 -> 1139.1406 | J12: =IF(COUNTIF($I$8:I12,"<0")>0,"Stop","Plant") -> Plant | K12: =IF(A12<2,0,IF(G12<G11,1,0)) -> 0 | L12: =SUM($G$8:G12) -> 29482.109 | M12: =L12/A12 -> 5896.4219
A13: 6 | B13: =A13*TOM_HPB*WEEKS*(1+TOM_DIM)^A13 -> 956.64294 | C13: =B13-B12 -> 231.91344 | D13: =MAX(0,MIN(C13,PERM_HOURS-B12)) -> 0 | E13: =C13-D13 -> 231.91344 | F13: =TOM_FERT -> 880 | G13: =D13*PERM_RATE+E13*TEMP_RATE+F13 -> 4906.275 | H13: =TOM_PRICE -> 8800 | I13: =H13-G13 -> 3893.725 | J13: =IF(COUNTIF($I$8:I13,"<0")>0,"Stop","Plant") -> Plant | K13: =IF(A13<2,0,IF(G13<G12,1,0)) -> 1 | L13: =SUM($G$8:G13) -> 34388.384 | M13: =L13/A13 -> 5731.3974
A14: 7 | B14: =A14*TOM_HPB*WEEKS*(1+TOM_DIM)^A14 -> 1227.6918 | C14: =B14-B13 -> 271.04883 | D14: =MAX(0,MIN(C14,PERM_HOURS-B13)) -> 0 | E14: =C14-D14 -> 271.04883 | F14: =TOM_FERT -> 880 | G14: =D14*PERM_RATE+E14*TEMP_RATE+F14 -> 5585.7089 | H14: =TOM_PRICE -> 8800 | I14: =H14-G14 -> 3214.2911 | J14: =IF(COUNTIF($I$8:I14,"<0")>0,"Stop","Plant") -> Plant | K14: =IF(A14<2,0,IF(G14<G13,1,0)) -> 0 | L14: =SUM($G$8:G14) -> 39974.093 | M14: =L14/A14 -> 5710.5848
A15: 8 | B15: =A15*TOM_HPB*WEEKS*(1+TOM_DIM)^A15 -> 1543.3839 | C15: =B15-B14 -> 315.69217 | D15: =MAX(0,MIN(C15,PERM_HOURS-B14)) -> 0 | E15: =C15-D15 -> 315.69217 | F15: =TOM_FERT -> 880 | G15: =D15*PERM_RATE+E15*TEMP_RATE+F15 -> 6360.7668 | H15: =TOM_PRICE -> 8800 | I15: =H15-G15 -> 2439.2332 | J15: =IF(COUNTIF($I$8:I15,"<0")>0,"Stop","Plant") -> Plant | K15: =IF(A15<2,0,IF(G15<G14,1,0)) -> 0 | L15: =SUM($G$8:G15) -> 46334.86 | M15: =L15/A15 -> 5791.8575
A16: 9 | B16: =A16*TOM_HPB*WEEKS*(1+TOM_DIM)^A16 -> 1909.9376 | C16: =B16-B15 -> 366.55369 | D16: =MAX(0,MIN(C16,PERM_HOURS-B15)) -> 0 | E16: =C16-D16 -> 366.55369 | F16: =TOM_FERT -> 880 | G16: =D16*PERM_RATE+E16*TEMP_RATE+F16 -> 7243.7793 | H16: =TOM_PRICE -> 8800 | I16: =H16-G16 -> 1556.2207 | J16: =IF(COUNTIF($I$8:I16,"<0")>0,"Stop","Plant") -> Plant | K16: =IF(A16<2,0,IF(G16<G15,1,0)) -> 0 | L16: =SUM($G$8:G16) -> 53578.639 | M16: =L16/A16 -> 5953.1822
A17: 10 | B17: =A17*TOM_HPB*WEEKS*(1+TOM_DIM)^A17 -> 2334.3682 | C17: =B17-B16 -> 424.43058 | D17: =MAX(0,MIN(C17,PERM_HOURS-B16)) -> 0 | E17: =C17-D17 -> 424.43058 | F17: =TOM_FERT -> 880 | G17: =D17*PERM_RATE+E17*TEMP_RATE+F17 -> 8248.5865 | H17: =TOM_PRICE -> 8800 | I17: =H17-G17 -> 551.41347 | J17: =IF(COUNTIF($I$8:I17,"<0")>0,"Stop","Plant") -> Plant | K17: =IF(A17<2,0,IF(G17<G16,1,0)) -> 0 | L17: =SUM($G$8:G17) -> 61827.226 | M17: =L17/A17 -> 6182.7226
A18: 11 | B18: =A18*TOM_HPB*WEEKS*(1+TOM_DIM)^A18 -> 2824.5855 | C18: =B18-B17 -> 490.21732 | D18: =MAX(0,MIN(C18,PERM_HOURS-B17)) -> 0 | E18: =C18-D18 -> 490.21732 | F18: =TOM_FERT -> 880 | G18: =D18*PERM_RATE+E18*TEMP_RATE+F18 -> 9390.7174 | H18: =TOM_PRICE -> 8800 | I18: =H18-G18 -> -590.71745 | J18: =IF(COUNTIF($I$8:I18,"<0")>0,"Stop","Plant") -> Stop | K18: =IF(A18<2,0,IF(G18<G17,1,0)) -> 0 | L18: =SUM($G$8:G18) -> 71217.943 | M18: =L18/A18 -> 6474.3585
A19: 12 | B19: =A19*TOM_HPB*WEEKS*(1+TOM_DIM)^A19 -> 3389.5026 | C19: =B19-B18 -> 564.91711 | D19: =MAX(0,MIN(C19,PERM_HOURS-B18)) -> 0 | E19: =C19-D19 -> 564.91711 | F19: =TOM_FERT -> 880 | G19: =D19*PERM_RATE+E19*TEMP_RATE+F19 -> 10687.589 | H19: =TOM_PRICE -> 8800 | I19: =H19-G19 -> -1887.5887 | J19: =IF(COUNTIF($I$8:I19,"<0")>0,"Stop","Plant") -> Stop | K19: =IF(A19<2,0,IF(G19<G18,1,0)) -> 0 | L19: =SUM($G$8:G19) -> 81905.532 | M19: =L19/A19 -> 6825.461
... A27: 20 | B27: =A27*TOM_HPB*WEEKS*(1+TOM_DIM)^A27 -> 12109.5 | C27: =B27-B26 -> 1651.2954 | D27: =MAX(0,MIN(C27,PERM_HOURS-B26)) -> 0 | E27: =C27-D27 -> 1651.2954 | F27: =TOM_FERT -> 880 | G27: =D27*PERM_RATE+E27*TEMP_RATE+F27 -> 29548.324 | H27: =TOM_PRICE -> 8800 | I27: =H27-G27 -> -20748.324 | J27: =IF(COUNTIF($I$8:I27,"<0")>0,"Stop","Plant") -> Stop | K27: =IF(A27<2,0,IF(G27<G26,1,0)) -> 0 | L27: =SUM($G$8:G27) -> 240334.37 | M27: =L27/A27 -> 12016.719
A30: CARROTS — standalone schedule (q = 0 to CAR_CAP, plus bed 21 past the cap: its P − MC is the cap's shadow price)
A31: q (beds) | B31: LABOR_HRS(q) | C31: MARGINAL_HRS(q) | D31: PERM_HRS(q) | E31: TEMP_HRS(q) | F31: Fertilizer, 1 bed | G31: MC(q) | H31: Price per bed | I31: P - MC(q) | J31: Decision (V7) | K31: Dip flag | L31: Cumulative VC(q) | M31: AVC(q)
A32: 0 | B32: =A32*CAR_HPB*WEEKS*(1+CAR_DIM)^A32 -> 0
A33: 1 | B33: =A33*CAR_HPB*WEEKS*(1+CAR_DIM)^A33 -> 30.75 | C33: =B33-B32 -> 30.75 | D33: =MAX(0,MIN(C33,PERM_HOURS-B32)) -> 30.75 | E33: =C33-D33 -> 0 | F33: =CAR_FERT -> 440 | G33: =D33*PERM_RATE+E33*TEMP_RATE+F33 -> 1507.7083 | H33: =CAR_PRICE -> 2094 | I33: =H33-G33 -> 586.29167 | J33: =IF(COUNTIF($I$33:I33,"<0")>0,"Stop","Plant") -> Plant | K33: =IF(A33<2,0,IF(G33<G32,1,0)) -> 0 | L33: =SUM($G$33:G33) -> 1507.7083 | M33: =L33/A33 -> 1507.7083
A34: 2 | B34: =A34*CAR_HPB*WEEKS*(1+CAR_DIM)^A34 -> 63.0375 | C34: =B34-B33 -> 32.2875 | D34: =MAX(0,MIN(C34,PERM_HOURS-B33)) -> 32.2875 | E34: =C34-D34 -> 0 | F34: =CAR_FERT -> 440 | G34: =D34*PERM_RATE+E34*TEMP_RATE+F34 -> 1561.0937 | H34: =CAR_PRICE -> 2094 | I34: =H34-G34 -> 532.90625 | J34: =IF(COUNTIF($I$33:I34,"<0")>0,"Stop","Plant") -> Plant | K34: =IF(A34<2,0,IF(G34<G33,1,0)) -> 0 | L34: =SUM($G$33:G34) -> 3068.8021 | M34: =L34/A34 -> 1534.401
A35: 3 | B35: =A35*CAR_HPB*WEEKS*(1+CAR_DIM)^A35 -> 96.920156 | C35: =B35-B34 -> 33.882656 | D35: =MAX(0,MIN(C35,PERM_HOURS-B34)) -> 33.882656 | E35: =C35-D35 -> 0 | F35: =CAR_FERT -> 440 | G35: =D35*PERM_RATE+E35*TEMP_RATE+F35 -> 1616.4811 | H35: =CAR_PRICE -> 2094 | I35: =H35-G35 -> 477.51888 | J35: =IF(COUNTIF($I$33:I35,"<0")>0,"Stop","Plant") -> Plant | K35: =IF(A35<2,0,IF(G35<G34,1,0)) -> 0 | L35: =SUM($G$33:G35) -> 4685.2832 | M35: =L35/A35 -> 1561.7611
A36: 4 | B36: =A36*CAR_HPB*WEEKS*(1+CAR_DIM)^A36 -> 132.45755 | C36: =B36-B35 -> 35.537391 | D36: =MAX(0,MIN(C36,PERM_HOURS-B35)) -> 35.537391 | E36: =C36-D36 -> 0 | F36: =CAR_FERT -> 440 | G36: =D36*PERM_RATE+E36*TEMP_RATE+F36 -> 1673.9372 | H36: =CAR_PRICE -> 2094 | I36: =H36-G36 -> 420.06283 | J36: =IF(COUNTIF($I$33:I36,"<0")>0,"Stop","Plant") -> Plant | K36: =IF(A36<2,0,IF(G36<G35,1,0)) -> 0 | L36: =SUM($G$33:G36) -> 6359.2204 | M36: =L36/A36 -> 1589.8051
A37: 5 | B37: =A37*CAR_HPB*WEEKS*(1+CAR_DIM)^A37 -> 169.71123 | C37: =B37-B36 -> 37.253685 | D37: =MAX(0,MIN(C37,PERM_HOURS-B36)) -> 37.253685 | E37: =C37-D37 -> 0 | F37: =CAR_FERT -> 440 | G37: =D37*PERM_RATE+E37*TEMP_RATE+F37 -> 1733.5307 | H37: =CAR_PRICE -> 2094 | I37: =H37-G37 -> 360.46927 | J37: =IF(COUNTIF($I$33:I37,"<0")>0,"Stop","Plant") -> Plant | K37: =IF(A37<2,0,IF(G37<G36,1,0)) -> 0 | L37: =SUM($G$33:G37) -> 8092.7511 | M37: =L37/A37 -> 1618.5502
A38: 6 | B38: =A38*CAR_HPB*WEEKS*(1+CAR_DIM)^A38 -> 208.74482 | C38: =B38-B37 -> 39.033583 | D38: =MAX(0,MIN(C38,PERM_HOURS-B37)) -> 39.033583 | E38: =C38-D38 -> 0 | F38: =CAR_FERT -> 440 | G38: =D38*PERM_RATE+E38*TEMP_RATE+F38 -> 1795.3328 | H38: =CAR_PRICE -> 2094 | I38: =H38-G38 -> 298.66724 | J38: =IF(COUNTIF($I$33:I38,"<0")>0,"Stop","Plant") -> Plant | K38: =IF(A38<2,0,IF(G38<G37,1,0)) -> 0 | L38: =SUM($G$33:G38) -> 9888.0839 | M38: =L38/A38 -> 1648.014
A39: 7 | B39: =A39*CAR_HPB*WEEKS*(1+CAR_DIM)^A39 -> 249.62401 | C39: =B39-B38 -> 40.879193 | D39: =MAX(0,MIN(C39,PERM_HOURS-B38)) -> 40.879193 | E39: =C39-D39 -> 0 | F39: =CAR_FERT -> 440 | G39: =D39*PERM_RATE+E39*TEMP_RATE+F39 -> 1859.4164 | H39: =CAR_PRICE -> 2094 | I39: =H39-G39 -> 234.58358 | J39: =IF(COUNTIF($I$33:I39,"<0")>0,"Stop","Plant") -> Plant | K39: =IF(A39<2,0,IF(G39<G38,1,0)) -> 0 | L39: =SUM($G$33:G39) -> 11747.5 | M39: =L39/A39 -> 1678.2143
A40: 8 | B40: =A40*CAR_HPB*WEEKS*(1+CAR_DIM)^A40 -> 292.4167 | C40: =B40-B39 -> 42.792687 | D40: =MAX(0,MIN(C40,PERM_HOURS-B39)) -> 42.792687 | E40: =C40-D40 -> 0 | F40: =CAR_FERT -> 440 | G40: =D40*PERM_RATE+E40*TEMP_RATE+F40 -> 1925.8572 | H40: =CAR_PRICE -> 2094 | I40: =H40-G40 -> 168.14281 | J40: =IF(COUNTIF($I$33:I40,"<0")>0,"Stop","Plant") -> Plant | K40: =IF(A40<2,0,IF(G40<G39,1,0)) -> 0 | L40: =SUM($G$33:G40) -> 13673.357 | M40: =L40/A40 -> 1709.1697
A41: 9 | B41: =A41*CAR_HPB*WEEKS*(1+CAR_DIM)^A41 -> 337.193 | C41: =B41-B40 -> 44.776306 | D41: =MAX(0,MIN(C41,PERM_HOURS-B40)) -> 44.776306 | E41: =C41-D41 -> 0 | F41: =CAR_FERT -> 440 | G41: =D41*PERM_RATE+E41*TEMP_RATE+F41 -> 1994.7329 | H41: =CAR_PRICE -> 2094 | I41: =H41-G41 -> 99.267136 | J41: =IF(COUNTIF($I$33:I41,"<0")>0,"Stop","Plant") -> Plant | K41: =IF(A41<2,0,IF(G41<G40,1,0)) -> 0 | L41: =SUM($G$33:G41) -> 15668.09 | M41: =L41/A41 -> 1740.8989
A42: 10 | B42: =A42*CAR_HPB*WEEKS*(1+CAR_DIM)^A42 -> 384.02536 | C42: =B42-B41 -> 46.832361 | D42: =MAX(0,MIN(C42,PERM_HOURS-B41)) -> 46.832361 | E42: =C42-D42 -> 0 | F42: =CAR_FERT -> 440 | G42: =D42*PERM_RATE+E42*TEMP_RATE+F42 -> 2066.1237 | H42: =CAR_PRICE -> 2094 | I42: =H42-G42 -> 27.876341 | J42: =IF(COUNTIF($I$33:I42,"<0")>0,"Stop","Plant") -> Plant | K42: =IF(A42<2,0,IF(G42<G41,1,0)) -> 0 | L42: =SUM($G$33:G42) -> 17734.214 | M42: =L42/A42 -> 1773.4214
A43: 11 | B43: =A43*CAR_HPB*WEEKS*(1+CAR_DIM)^A43 -> 432.9886 | C43: =B43-B42 -> 48.963234 | D43: =MAX(0,MIN(C43,PERM_HOURS-B42)) -> 48.963234 | E43: =C43-D43 -> 0 | F43: =CAR_FERT -> 440 | G43: =D43*PERM_RATE+E43*TEMP_RATE+F43 -> 2140.1123 | H43: =CAR_PRICE -> 2094 | I43: =H43-G43 -> -46.112285 | J43: =IF(COUNTIF($I$33:I43,"<0")>0,"Stop","Plant") -> Stop | K43: =IF(A43<2,0,IF(G43<G42,1,0)) -> 0 | L43: =SUM($G$33:G43) -> 19874.326 | M43: =L43/A43 -> 1806.7569
A44: 12 | B44: =A44*CAR_HPB*WEEKS*(1+CAR_DIM)^A44 -> 484.15998 | C44: =B44-B43 -> 51.17138 | D44: =MAX(0,MIN(C44,PERM_HOURS-B43)) -> 51.17138 | E44: =C44-D44 -> 0 | F44: =CAR_FERT -> 440 | G44: =D44*PERM_RATE+E44*TEMP_RATE+F44 -> 2216.784 | H44: =CAR_PRICE -> 2094 | I44: =H44-G44 -> -122.78402 | J44: =IF(COUNTIF($I$33:I44,"<0")>0,"Stop","Plant") -> Stop | K44: =IF(A44<2,0,IF(G44<G43,1,0)) -> 0 | L44: =SUM($G$33:G44) -> 22091.11 | M44: =L44/A44 -> 1840.9259
... A52: 20 | B52: =A52*CAR_HPB*WEEKS*(1+CAR_DIM)^A52 -> 983.16986 | C52: =B52-B51 -> 71.939258 | D52: =MAX(0,MIN(C52,PERM_HOURS-B51)) -> 0 | E52: =C52-D52 -> 71.939258 | F52: =CAR_FERT -> 440 | G52: =D52*PERM_RATE+E52*TEMP_RATE+F52 -> 1688.9455 | H52: =CAR_PRICE -> 2094 | I52: =H52-G52 -> 405.05454 | J52: =IF(COUNTIF($I$33:I52,"<0")>0,"Stop","Plant") -> Stop | K52: =IF(A52<2,0,IF(G52<G51,1,0)) -> 0 | L52: =SUM($G$33:G52) -> 38368.921 | M52: =L52/A52 -> 1918.4461
A53: 21 | B53: =A53*CAR_HPB*WEEKS*(1+CAR_DIM)^A53 -> 1058.1366 | C53: =B53-B52 -> 74.966702 | D53: =MAX(0,MIN(C53,PERM_HOURS-B52)) -> 0 | E53: =C53-D53 -> 74.966702 | F53: =CAR_FERT -> 440 | G53: =D53*PERM_RATE+E53*TEMP_RATE+F53 -> 1741.5052 | H53: =CAR_PRICE -> 2094 | I53: =H53-G53 -> 352.49475 | J53: Past cap | L53: =SUM($G$33:G53) -> 40110.426 | M53: =L53/A53 -> 1910.0203
A55: MESCLUN — standalone schedule (q = 0 to MES_CAP, plus bed 31 past the cap: its P − MC is the cap's shadow price)
A56: q (beds) | B56: LABOR_HRS(q) | C56: MARGINAL_HRS(q) | D56: PERM_HRS(q) | E56: TEMP_HRS(q) | F56: Fertilizer, 1 bed | G56: MC(q) | H56: Price per bed | I56: P - MC(q) | J56: Decision (V7) | K56: Dip flag | L56: Cumulative VC(q) | M56: AVC(q)
A57: 0 | B57: =A57*MES_HPB*WEEKS*(1+MES_DIM)^A57 -> 0
A58: 1 | B58: =A58*MES_HPB*WEEKS*(1+MES_DIM)^A58 -> 45.5625 | C58: =B58-B57 -> 45.5625 | D58: =MAX(0,MIN(C58,PERM_HOURS-B57)) -> 45.5625 | E58: =C58-D58 -> 0 | F58: =MES_FERT -> 880 | G58: =D58*PERM_RATE+E58*TEMP_RATE+F58 -> 2462.0312 | H58: =MES_PRICE -> 2700 | I58: =H58-G58 -> 237.96875 | J58: =IF(COUNTIF($I$58:I58,"<0")>0,"Stop","Plant") -> Plant | K58: =IF(A58<2,0,IF(G58<G57,1,0)) -> 0 | L58: =SUM($G$58:G58) -> 2462.0312 | M58: =L58/A58 -> 2462.0312
...

Sheet Optimization
A1: Optimization — season profit at the current bed counts
A2: Everything here is driven by TOM_BEDS / CAR_BEDS / MES_BEDS on the Inputs sheet. Season profit in OUT_SEASON_PROFIT is the Solver objective.
A4: The decision
A5: Output | B5: Value | C5: Unit | D5: What it reports
A6: OUT_TOM_BEDS | B6: =TOM_BEDS -> 10 | C6: beds | D6: Optimal tomato beds
A7: OUT_CAR_BEDS | B7: =CAR_BEDS -> 20 | C7: beds | D7: Optimal carrot beds
A8: OUT_MES_BEDS | B8: =MES_BEDS -> 30 | C8: beds | D8: Optimal mesclun beds
A9: OUT_BEDS_USED | B9: =OUT_TOM_BEDS+OUT_CAR_BEDS+OUT_MES_BEDS -> 60 | C9: beds | D9: Total beds planted
A10: OUT_BEDS_IDLE | B10: =FARM_BED_CAP-OUT_BEDS_USED -> 4 | C10: beds | D10: FARM_BED_CAP less beds planted
A12: Labor
A13: Output | B13: Value | C13: Unit | D13: What it reports
A14: Tomato field hours | B14: =TOM_BEDS*TOM_HPB*WEEKS*(1+TOM_DIM)^TOM_BEDS -> 2334.3682 | C14: hours | D14: LABOR_HRS(q) = q x HRS_PER_WEEK_PER_BED x WEEKS x (1 + DIM_PCT)^q
A15: Carrot field hours | B15: =CAR_BEDS*CAR_HPB*WEEKS*(1+CAR_DIM)^CAR_BEDS -> 983.16986 | C15: hours | D15: LABOR_HRS(q) = q x HRS_PER_WEEK_PER_BED x WEEKS x (1 + DIM_PCT)^q
A16: Mesclun field hours | B16: =MES_BEDS*MES_HPB*WEEKS*(1+MES_DIM)^MES_BEDS -> 1959.678 | C16: hours | D16: LABOR_HRS(q) = q x HRS_PER_WEEK_PER_BED x WEEKS x (1 + DIM_PCT)^q
A17: OUT_TOTAL_HOURS | B17: =B14+B15+B16 -> 5277.2161 | C17: hours | D17: Total field hours required (TOTAL_LABOR / TOTAL_LABOR_HOURS)
A18: OUT_PERM_HOURS | B18: =MIN(OUT_TOTAL_HOURS,PERM_HOURS) -> 720 | C18: hours | D18: Hours worked by the farmer — her hours are used first
A19: OUT_TEMP_HOURS | B19: =MAX(0,OUT_TOTAL_HOURS-PERM_HOURS) -> 4557.2161 | C19: hours | D19: Hours worked by temporary labor
A20: OUT_TEMP_WORKERS | B20: =ROUNDUP(OUT_TEMP_HOURS/TEMP_WORKER_HRS,0) -> 4 | C20: workers | D20: Temps are hired by the season: a worker needed for one hour is a worker hired
A21: Permanent labor cost | B21: =OUT_PERM_HOURS*PERM_RATE -> 25000 | C21: $ | D21: Only the field half of FARMER_SALARY is charged (spec Convention 2)
A22: Temporary labor cost | B22: =OUT_TEMP_HOURS*TEMP_RATE -> 79118.335 | C22: $ | D22: Charged per hour worked, not per whole seasonal contract (spec Convention 3)
A23: OUT_BLENDED_RATE | B23: =IF(OUT_TOTAL_HOURS=0,0,OUT_LABOR_COST/OUT_TOTAL_HOURS) -> 19.729784 | C23: $ per hour | D23: Total labor dollars / total labor hours. Used only for the per-crop P&L (spec §3H).
A25: Money
A26: Output | B26: Value | C26: Unit | D26: What it reports
A27: OUT_REVENUE | B27: =SUM(OUT_CROP_REVENUE) -> 210880 | C27: $ | D27: Total season revenue
A28: OUT_LABOR_COST | B28: =B21+B22 -> 104118.34 | C28: $ | D28: Permanent plus temporary labor
A29: OUT_FERT_COST | B29: =SUM(OUT_CROP_FERT_COST) -> 44000 | C29: $ | D29: Fertilizer, all crops
A30: OUT_FIXED_COST | B30: =FIXED_COST -> 20000 | C30: $ | D30: Fixed cost — not allocated to crops, not in MC(q)
A31: OUT_TOTAL_COST | B31: =OUT_LABOR_COST+OUT_FERT_COST+OUT_FIXED_COST -> 168118.34 | C31: $ | D31: All three added
A32: OUT_SEASON_PROFIT | B32: =OUT_REVENUE-OUT_TOTAL_COST -> 42761.665 | C32: $ | D32: Revenue less total cost — the Solver objective
A34: Per-crop P&L — labor allocated at OUT_BLENDED_RATE (spec §3H)
A35: No crop hires the temporary workers; the season does. Because the blended rate is total labor dollars divided by total labor hours, the three crop labor costs add back to OUT_LABOR_COST exactly.
A36: Crop | B36: 10 | C36: Field hours | D36: OUT_CROP_REVENUE | E36: OUT_CROP_FERT_COST | F36: OUT_CROP_LABOR_COST | G36: OUT_CROP_PROFIT
A37: Tomatoes | B37: =TOM_BEDS -> 10 | C37: =B14 -> 2334.3682 | D37: =TOM_BEDS*TOM_PRICE -> 88000 | E37: =TOM_BEDS*TOM_FERT -> 8800 | F37: =C37*OUT_BLENDED_RATE -> 46056.581 | G37: =D37-E37-F37 -> 33143.419
A38: Carrots | B38: =CAR_BEDS -> 20 | C38: =B15 -> 983.16986 | D38: =CAR_BEDS*CAR_PRICE -> 41880 | E38: =CAR_BEDS*CAR_FERT -> 8800 | F38: =C38*OUT_BLENDED_RATE -> 19397.729 | G38: =D38-E38-F38 -> 13682.271
A39: Mesclun | B39: =MES_BEDS -> 30 | C39: =B16 -> 1959.678 | D39: =MES_BEDS*MES_PRICE -> 81000 | E39: =MES_BEDS*MES_FERT -> 26400 | F39: =C39*OUT_BLENDED_RATE -> 38664.025 | G39: =D39-E39-F39 -> 15935.975
A40: Total | B40: =SUM(B37:B39) -> 60 | C40: =SUM(C37:C39) -> 5277.2161 | D40: =SUM(D37:D39) -> 210880 | E40: =SUM(E37:E39) -> 44000 | F40: =SUM(F37:F39) -> 104118.34 | G40: =SUM(G37:G39) -> 62761.665
A41: Less OUT_FIXED_COST | G41: =-OUT_FIXED_COST -> -20000
A42: Reconciles to OUT_SEASON_PROFIT | G42: =G40+G41 -> 42761.665
A44: OUT_PNL_RECONCILES | B44: =IF(AND(ABS(SUM(OUT_CROP_LABOR_COST)-OUT_LABOR_COST)<0.000001,ABS(SUM(OUT_CROP_PROFIT)-OUT_FIXED_COST-OUT_SEASON_PROFIT)<0.000001),"OK","VIOLATED") -> OK | D44: OK when the three crop labor costs sum to OUT_LABOR_COST and the three crop profits less OUT_FIXED_COST equal OUT_SEASON_PROFIT.
A46: Solver setup (V6)
...

Sheet Validation
A1: Validation
A2: Every check below is computed in this workbook and displays OK or VIOLATED — no other wording, so a failed check is visible at a glance rather than read for.
A4: The constraints (V5 — 'all constraints satisfied')
A5: Constraint | B5: Check | C5: Rule | D5: Note
A6: Tomato bed cap | B6: =IF(TOM_BEDS<=TOM_CAP,"OK","VIOLATED") -> OK | C6: TOM_BEDS <= TOM_CAP (20)
A7: Carrot bed cap | B7: =IF(CAR_BEDS<=CAR_CAP,"OK","VIOLATED") -> OK | C7: CAR_BEDS <= CAR_CAP (20)
A8: Mesclun bed cap | B8: =IF(MES_BEDS<=MES_CAP,"OK","VIOLATED") -> OK | C8: MES_BEDS <= MES_CAP (30)
A9: Farm bed cap | B9: =IF(OUT_BEDS_USED<=FARM_BED_CAP,"OK","VIOLATED") -> OK | C9: TOM_BEDS + CAR_BEDS + MES_BEDS <= FARM_BED_CAP (64)
A10: Temporary workers | B10: =IF(OUT_TEMP_WORKERS<=TEMP_WORKERS_MAX,"OK","VIOLATED") -> OK | C10: OUT_TEMP_WORKERS <= TEMP_WORKERS_MAX (4). The constraint is on whole workers, not hours.
A11: Whole beds | B11: =IF(AND(TOM_BEDS=INT(TOM_BEDS),CAR_BEDS=INT(CAR_BEDS),MES_BEDS=INT(MES_BEDS)),"OK","VIOLATED") -> OK | C11: All three bed counts are integers
A12: Non-negative | B12: =IF(AND(TOM_BEDS>=0,CAR_BEDS>=0,MES_BEDS>=0),"OK","VIOLATED") -> OK | C12: All three bed counts are >= 0
A14: OUT_CONSTRAINTS_OK | B14: =IF(COUNTIF($B$6:$B$12,"VIOLATED")=0,"OK","VIOLATED") -> OK | D14: OK only when every constraint check above reads OK.
A16: V1 — Hand check, one tomato bed
A17: Item | B17: Check / value | C17: Expected | D17: Note
A18: Model, LABOR_HRS at q = 1 (tomato) | B18: =INDEX('Marginal Analysis'!$B$8:$B$27,1) -> 99 | C18: 99 | D18: 1 x 2.5 x 36 x 1.10 = 99 hours, computed by hand.
A19: V1 check | B19: =IF(ABS(B18-C18)<0.000000001,"OK","VIOLATED") -> OK | C19: Would catch a dropped (1 + dim)^q term: without the exponent the same cell returns 90 hours.
A21: V2 — Mid-schedule hand check
A22: Taken from the middle of a schedule, not from either end: an endpoint can agree by accident where the interior cannot. V1 checks the hours function at q = 1, where 99 hours is easy to see; this checks the cost of a bed ten rows down, where the permanent hours are long gone and every term of MC(q) is in play. Work the arithmetic yourself from the case table and enter the result in the shaded cell; the check is a formula. Copying the figure out of the model defeats the check.
A23: Item | B23: Value | C23: Expected | D23: Note
A24: This model, MC of tomato bed 10 | B24: =INDEX('Marginal Analysis'!$G$8:$G$27,10) -> 8248.5865 | D24: Spec V2 detail: this model returns $8,249.
A25: Hand-computed, MC of tomato bed 10 <- ENTER OBSERVED | B25: 8248.59 | D25: Observed input, not a calculated cell. Left empty until the arithmetic is done; the check below reads VIOLATED while it is empty. LABOR_HRS(10) - LABOR_HRS(9) = 424.4306 hours, all of it temporary, at TEMP_RATE, plus one bed of fertilizer.
A26: V2 check | B26: =IF(AND(ISNUMBER(B25),ROUND(B24,0)=ROUND(B25,0)),"OK","VIOLATED") -> OK | C26: Must agree to the dollar.
A28: V3 — Solver from two starting points
A29: Run Solver from 0/0/0 and again from 15/0/0 and record the season profit each run reports. Both runs have to agree on season profit; they do not have to arrive by the same route. If the profit differs, one of them found a local optimum and the result is not the answer.
A30: Item | B30: Value | C30: Expected | D30: Note
A31: Season profit from start 0/0/0 <- ENTER OBSERVED | B31: 42761.66
A32: Season profit from start 15/0/0 <- ENTER OBSERVED | B32: 42761.66 | D32: Both start points must be feasible: an infeasible start returns no profit figure, and this check cannot pass without one. 20/0/0 was the earlier choice and is infeasible - 12,109 hours, about eight temp workers against a cap of four - and every single-bed neighbour of it is infeasible too, so Solver has no route out. 15/0/0 is the nearest tomato-only start that fits the four-worker cap, and it is thirty hill-climb steps from the answer.
A33: V3 check | B33: =IF(AND(ISNUMBER(B31),ISNUMBER(B32),ROUND(B31,0)=ROUND(B32,0)),"OK","VIOLATED") -> OK | C33: Both runs agree on season profit to the dollar.
A35: V4 — Acceptance criteria
A36: Check | B36: Result | C36: Required | D36: Note
A37: Optimal mix | B37: =IF(AND(OUT_TOM_BEDS=10,OUT_CAR_BEDS=20,OUT_MES_BEDS=30),"OK","VIOLATED") -> OK | C37: 10 tomatoes / 20 carrots / 30 mesclun | D37: ="Model: "&OUT_TOM_BEDS&" / "&OUT_CAR_BEDS&" / "&OUT_MES_BEDS -> Model: 10 / 20 / 30
A38: Season profit | B38: =IF(AND(ROUND(OUT_SEASON_PROFIT,0)=42762,OUT_SEASON_PROFIT<=42762),"OK","VIOLATED") -> OK | C38: Rounds to $42,762 and does not exceed it | D38: ="Model: "&TEXT(OUT_SEASON_PROFIT,"$#,##0.00") -> Model: $42,761.66
A39: Standalone P = MC points | B39: =IF(AND(OUT_CROSSING_TOM=10,OUT_CROSSING_CAR=10,OUT_CROSSING_MES=6),"OK","VIOLATED") -> OK | C39: Tomatoes 10 / Carrots 10 / Mesclun 6 — exact bed counts, no tolerance | D39: ="Model: "&OUT_CROSSING_TOM&" / "&OUT_CROSSING_CAR&" / "&OUT_CROSSING_MES -> Model: 10 / 10 / 6
A41: V5 — Integrity
A42: Check | B42: Result | C42: Required | D42: Note
A43: No spreadsheet errors | B43: =IF(SUMPRODUCT(--ISERROR('Marginal Analysis'!$B$8:$K$27))+SUMPRODUCT(--ISERROR('Marginal Analysis'!$B$33:$K$52))+SUMPRODUCT(--ISERROR('Marginal Analysis'!$B$58:$K$87))+SUMPRODUCT(--ISERROR(Optimization!$B$5:$B$32))+SUMPRODUCT(--ISERROR(Optimization!$B$37:$G$39))=0,"OK","VIOLATED") -> OK | C43: Zero error cells across the schedules and the optimization block | D43: ="Error cells found: "&(SUMPRODUCT(--ISERROR('Marginal Analysis'!$B$8:$K$27))+SUMPRODUCT(--ISERROR('Marginal Analysis'!$B$33:$K$52))+SUMPRODUCT(--ISERROR('Marginal Analysis'!$B$58:$K$87))+SUMPRODUCT(--ISERROR(Optimization!$B$5:$B$32))+SUMPRODUCT(--ISERROR(Optimization!$B$37:$G$39))) -> Error cells found: 0
A44: All constraints satisfied | B44: =OUT_CONSTRAINTS_OK -> OK | C44: OUT_CONSTRAINTS_OK reads OK
A45: Per-crop P&L reconciles | B45: =OUT_PNL_RECONCILES -> OK | C45: Crop labor costs sum to OUT_LABOR_COST; crop profits less fixed cost equal season profit
A46: Rates derived, not typed | B46: =IF(AND(ABS(PERM_RATE-FARMER_SALARY/2/PERM_HOURS)<0.000000001,ABS(TEMP_RATE-TEMP_WORKER_PAY/TEMP_WORKER_HRS)<0.000000001,ABS(PERM_RATE-34.72)>0.0001),"OK","VIOLATED") -> OK | C46: Exact quotients, not the printed $34.72 / $17.36 | D46: Typing the printed values returns a season profit of $42,768 against a check figure of $42,762.
A48: V7 — The crossing rule
...
